<?xml version="1.0" ?>
<robot name="HEBI_3_DOF_Arm_1">
  <!--Joints-->
  <joint name="world_to_base_link" type="fixed">
    <parent link="world"/>
    <child link="base_link"/>
  </joint>
  <joint name="base_link_to_a_2043_01_5Z" type="fixed">
    <parent link="base_link"/>
    <child link="a_2043_01_5Z"/>
  </joint>
  <joint name="a_2043_01_5Z_to_hebi_x5_4_3Z" type="fixed">
    <parent link="a_2043_01_5Z"/>
    <child link="hebi_x5_4_3Z"/>
    <origin rpy="0.0 -5.08239990574e-17 -1.73333696049e-33" xyz="8.71763536758e-24 1.61232339957e-23 1e-23"/>
  </joint>
  <joint name="HEBI/Base/X5_4" type="revolute">
    <parent link="hebi_x5_4_3Z"/>
    <child link="a_2040_01r_1Z"/>
    <axis xyz="-2.77554010017e-17 -1.73472348e-16 1.0"/>
    <dynamics damping="0.5" friction="0.06"/>
    <limit effort="100" lower="-3.14" upper="+3.14" velocity="100"/>
    <origin rpy="0.0 3.34767643574e-17 7.733222874e-33" xyz="-5.55318730444e-17 -2.96636102637e-18 0.03"/>
  </joint>
  <gazebo reference="HEBI/Base/X5_4">
    <implicitSpringDamper>True</implicitSpringDamper>
  </gazebo>
  <joint name="a_2040_01r_1Z_to_hebi_x5_9_7Z" type="fixed">
    <parent link="a_2040_01r_1Z"/>
    <child link="hebi_x5_9_7Z"/>
    <origin rpy="1.57079632679 3.08148791102e-33 -5.08239990574e-17" xyz="4.80186749853e-17 -0.0375 0.055"/>
  </joint>
  <joint name="HEBI/Shoulder/X5_9" type="revolute">
    <parent link="hebi_x5_9_7Z"/>
    <child link="a_2038_02_8Z"/>
    <axis xyz="-2.77554010017e-17 -1.66533454e-16 1.0"/>
    <dynamics damping="0.5" friction="0.06"/>
    <limit effort="100" lower="-0.2" upper="+3.14" velocity="100"/>
    <origin rpy="0.0 -2.77555756e-17 0.0" xyz="-5.35847694878e-17 2.34257058104e-17 0.03"/>
  </joint>
  <gazebo reference="HEBI/Shoulder/X5_9">
    <implicitSpringDamper>True</implicitSpringDamper>
  </gazebo>
  <joint name="a_2038_02_8Z_to_tubepar_9Z" type="fixed">
    <parent link="a_2038_02_8Z"/>
    <child link="tubepar_9Z"/>
    <origin rpy="1.57079632679 -1.57079632679 0.0" xyz="0.0135 -9.540978845e-20 0.02"/>
  </joint>
  <joint name="tubepar_9Z_to_a_2039_02_10Z" type="fixed">
    <parent link="tubepar_9Z"/>
    <child link="a_2039_02_10Z"/>
    <origin rpy="1.57079632679 2.50240867501e-14 -1.57079632679" xyz="4.84783703319e-18 -0.3 5.20417041e-18"/>
  </joint>
  <joint name="a_2039_02_10Z_to_hebi_x5_4_6Z" type="fixed">
    <parent link="a_2039_02_10Z"/>
    <child link="hebi_x5_4_6Z"/>
    <origin rpy="1.22464679915e-16 1.04083409e-17 2.50240867501e-14" xyz="0.014 3.34058705353e-16 0.02"/>
  </joint>
  <joint name="HEBI/Elbow/X5_4" type="revolute">
    <parent link="hebi_x5_4_6Z"/>
    <child link="a_2038_02_2Z"/>
    <axis xyz="-8.89879155574e-17 -1.5959456e-16 1.0"/>
    <dynamics damping="0.5" friction="0.06"/>
    <limit effort="100" lower="-2.8" upper="+2.8" velocity="100"/>
    <origin rpy="0.0 -2.77555756e-17 -3.08148791102e-33" xyz="-5.95130563275e-17 -4.7878368e-18 0.03"/>
  </joint>
  <gazebo reference="HEBI/Elbow/X5_4">
    <implicitSpringDamper>True</implicitSpringDamper>
  </gazebo>
  <joint name="a_2038_02_2Z_to_tubepar_11Z" type="fixed">
    <parent link="a_2038_02_2Z"/>
    <child link="tubepar_11Z"/>
    <origin rpy="1.57079632679 -1.57079632679 0.0" xyz="0.0135 5.1174342845e-19 0.02"/>
  </joint>
  <joint name="tubepar_11Z_to_a_2039_02_4Z" type="fixed">
    <parent link="tubepar_11Z"/>
    <child link="a_2039_02_4Z"/>
    <origin rpy="1.57079632679 2.50240867501e-14 -1.57079632679" xyz="-2.94658008559e-18 -0.3 9.0066843052e-18"/>
  </joint>
  <!--Gazebo Plugins-->
  <gazebo>
    <plugin filename="libhebiros_gazebo_plugin.so" name="hebiros_gazebo_plugin"/>
  </gazebo>
  <!--Links-->
  <link name="world"/>
  <link name="base_link">
    <!--Transformation from CyPhy2CAD global reference frame to base_link-->
    <CyPhy2CAD>
      <CADAssembly_metrics>
        <RotationMatrix>
          <Row>
            <Column Value="1.0"/>
            <Column Value="0.0"/>
            <Column Value="0.0"/>
          </Row>
          <Row>
            <Column Value="0.0"/>
            <Column Value="1.0"/>
            <Column Value="0.0"/>
          </Row>
          <Row>
            <Column Value="0.0"/>
            <Column Value="0.0"/>
            <Column Value="1.0"/>
          </Row>
        </RotationMatrix>
        <Translation X="1e-20" Y="1e-20" Z="1e-20"/>
      </CADAssembly_metrics>
    </CyPhy2CAD>
  </link>
  <link name="a_2038_02_2Z">
    <visual>
      <origin rpy="0 0 0" xyz="5.68434188608e-17 9.86076128129e-34 3.48065554802e-33"/>
      <geometry>
        <mesh filename="package://openmeta_generated_urdf_package/meshes/a_2038_02_2z_prt.stl" scale="0.001 0.001 0.001"/>
      </geometry>
    </visual>
    <collision>
      <origin rpy="0 0 0" xyz="5.68434188608e-17 9.86076128129e-34 3.48065554802e-33"/>
      <geometry>
        <mesh filename="package://openmeta_generated_urdf_package/meshes/a_2038_02_2z_prt.stl" scale="0.001 0.001 0.001"/>
      </geometry>
    </collision>
    <inertial>
      <origin rpy="0 0 0" xyz="0.0176052907699 9.86076128129e-34 0.0142788404199"/>
      <mass value="0.059108249978877175"/>
      <inertia ixx="2.3632587043e-05" ixy="0.0" ixz="-3.93131579939e-06" iyy="2.03298829586e-05" iyz="0.0" izz="2.72912531732e-05"/>
    </inertial>
  </link>
  <gazebo reference="a_2038_02_2Z">
    <selfCollide>True</selfCollide>
    <material>Gazebo/Black</material>
    <mu1>0.1</mu1>
    <mu2>0.1</mu2>
    <kp>100000</kp>
    <kd>1</kd>
    <minDepth>0.001</minDepth>
    <maxVel>100</maxVel>
  </gazebo>
  <link name="a_2038_02_8Z">
    <visual>
      <origin rpy="0 0 0" xyz="5.68994337913e-17 -9.87047832275e-34 -4.47113330557e-33"/>
      <geometry>
        <mesh filename="package://openmeta_generated_urdf_package/meshes/a_2038_02_8z_prt.stl" scale="0.001 0.001 0.001"/>
      </geometry>
    </visual>
    <collision>
      <origin rpy="0 0 0" xyz="5.68994337913e-17 -9.87047832275e-34 -4.47113330557e-33"/>
      <geometry>
        <mesh filename="package://openmeta_generated_urdf_package/meshes/a_2038_02_8z_prt.stl" scale="0.001 0.001 0.001"/>
      </geometry>
    </collision>
    <inertial>
      <origin rpy="0 0 0" xyz="0.0176052907699 -9.87047832275e-34 0.0142788404199"/>
      <mass value="0.059108249978877175"/>
      <inertia ixx="2.3632587043e-05" ixy="0.0" ixz="-3.93131579939e-06" iyy="2.03298829586e-05" iyz="0.0" izz="2.72912531732e-05"/>
    </inertial>
  </link>
  <gazebo reference="a_2038_02_8Z">
    <selfCollide>True</selfCollide>
    <material>Gazebo/Black</material>
    <mu1>0.1</mu1>
    <mu2>0.1</mu2>
    <kp>100000</kp>
    <kd>1</kd>
    <minDepth>0.001</minDepth>
    <maxVel>100</maxVel>
  </gazebo>
  <link name="a_2039_02_10Z">
    <visual>
      <origin rpy="0 0 0" xyz="0.014 3.48269560069e-16 0.02"/>
      <geometry>
        <mesh filename="package://openmeta_generated_urdf_package/meshes/a_2039_02_10z_prt.stl" scale="0.001 0.001 0.001"/>
      </geometry>
    </visual>
    <collision>
      <origin rpy="0 0 0" xyz="0.014 3.48269560069e-16 0.02"/>
      <geometry>
        <mesh filename="package://openmeta_generated_urdf_package/meshes/a_2039_02_10z_prt.stl" scale="0.001 0.001 0.001"/>
      </geometry>
    </collision>
    <inertial>
      <origin rpy="0 0 0" xyz="0.00256411047128 3.48269560069e-16 0.00833404763152"/>
      <mass value="0.08075605008850124"/>
      <inertia ixx="3.54766366127e-05" ixy="0.0" ixz="-8.29679742245e-06" iyy="3.7139980371e-05" iyz="0.0" izz="5.23238184568e-05"/>
    </inertial>
  </link>
  <gazebo reference="a_2039_02_10Z">
    <selfCollide>True</selfCollide>
    <material>Gazebo/Black</material>
    <mu1>0.1</mu1>
    <mu2>0.1</mu2>
    <kp>100000</kp>
    <kd>1</kd>
    <minDepth>0.001</minDepth>
    <maxVel>100</maxVel>
  </gazebo>
  <link name="a_2039_02_4Z">
    <visual>
      <origin rpy="0 0 0" xyz="0.014 3.47783837497e-16 0.02"/>
      <geometry>
        <mesh filename="package://openmeta_generated_urdf_package/meshes/a_2039_02_4z_prt.stl" scale="0.001 0.001 0.001"/>
      </geometry>
    </visual>
    <collision>
      <origin rpy="0 0 0" xyz="0.014 3.47783837497e-16 0.02"/>
      <geometry>
        <mesh filename="package://openmeta_generated_urdf_package/meshes/a_2039_02_4z_prt.stl" scale="0.001 0.001 0.001"/>
      </geometry>
    </collision>
    <inertial>
      <origin rpy="0 0 0" xyz="0.00256411047128 3.47783837497e-16 0.00833404763152"/>
      <mass value="0.08075605008850124"/>
      <inertia ixx="3.54766366127e-05" ixy="0.0" ixz="-8.29679742245e-06" iyy="3.7139980371e-05" iyz="0.0" izz="5.23238184568e-05"/>
    </inertial>
  </link>
  <gazebo reference="a_2039_02_4Z">
    <selfCollide>True</selfCollide>
    <material>Gazebo/Black</material>
    <mu1>0.1</mu1>
    <mu2>0.1</mu2>
    <kp>100000</kp>
    <kd>1</kd>
    <minDepth>0.001</minDepth>
    <maxVel>100</maxVel>
  </gazebo>
  <link name="a_2040_01r_1Z">
    <visual>
      <origin rpy="0 0 0" xyz="-0.00144337567 -0.0366111248 -0.0110127649"/>
      <geometry>
        <mesh filename="package://openmeta_generated_urdf_package/meshes/a_2040_01r_1z_prt.stl" scale="0.001 0.001 0.001"/>
      </geometry>
    </visual>
    <collision>
      <origin rpy="0 0 0" xyz="-0.00144337567 -0.0366111248 -0.0110127649"/>
      <geometry>
        <mesh filename="package://openmeta_generated_urdf_package/meshes/a_2040_01r_1z_prt.stl" scale="0.001 0.001 0.001"/>
      </geometry>
    </collision>
    <inertial>
      <origin rpy="0 0 0" xyz="0.00491688893766 -0.0251584176519 0.0321388430548"/>
      <mass value="0.20914931631287276"/>
      <inertia ixx="0.000172164331359" ixy="6.97960030475e-06" ixz="1.86510590224e-06" iyy="0.000214507296155" iyz="3.45432088412e-05" izz="0.00012102414398"/>
    </inertial>
  </link>
  <gazebo reference="a_2040_01r_1Z">
    <selfCollide>True</selfCollide>
    <material>Gazebo/Black</material>
    <mu1>0.1</mu1>
    <mu2>0.1</mu2>
    <kp>100000</kp>
    <kd>1</kd>
    <minDepth>0.001</minDepth>
    <maxVel>100</maxVel>
  </gazebo>
  <link name="a_2043_01_5Z">
    <visual>
      <origin rpy="0 0 0" xyz="1e-23 1e-23 1e-23"/>
      <geometry>
        <mesh filename="package://openmeta_generated_urdf_package/meshes/a_2043_01_5z_prt.stl" scale="0.001 0.001 0.001"/>
      </geometry>
    </visual>
    <collision>
      <origin rpy="0 0 0" xyz="1e-23 1e-23 1e-23"/>
      <geometry>
        <mesh filename="package://openmeta_generated_urdf_package/meshes/a_2043_01_5z_prt.stl" scale="0.001 0.001 0.001"/>
      </geometry>
    </collision>
    <inertial>
      <origin rpy="0 0 0" xyz="-0.00139419949295 1e-23 -0.00293190489101"/>
      <mass value="0.06272938391183215"/>
      <inertia ixx="7.22571415296e-05" ixy="2.96268938113e-10" ixz="5.68510520871e-08" iyy="1.34631068457e-05" iyz="0.0" izz="8.48613385518e-05"/>
    </inertial>
  </link>
  <gazebo reference="a_2043_01_5Z">
    <selfCollide>True</selfCollide>
    <material>Gazebo/Black</material>
    <mu1>0.1</mu1>
    <mu2>0.1</mu2>
    <kp>100000</kp>
    <kd>1</kd>
    <minDepth>0.001</minDepth>
    <maxVel>100</maxVel>
  </gazebo>
  <link name="tubepar_9Z">
    <visual>
      <origin rpy="0 0 0" xyz="4.84783703319e-18 -0.3 5.20417041e-18"/>
      <geometry>
        <mesh filename="package://openmeta_generated_urdf_package/meshes/tubepar_9z_prt.stl" scale="0.001 0.001 0.001"/>
      </geometry>
    </visual>
    <collision>
      <origin rpy="0 0 0" xyz="4.84783703319e-18 -0.3 5.20417041e-18"/>
      <geometry>
        <mesh filename="package://openmeta_generated_urdf_package/meshes/tubepar_9z_prt.stl" scale="0.001 0.001 0.001"/>
      </geometry>
    </collision>
    <inertial>
      <origin rpy="0 0 0" xyz="4.84783703319e-18 -0.15 5.20417041e-18"/>
      <mass value="0.12133427279164029"/>
      <inertia ixx="0.000923727684155" ixy="0.0" ixz="0.0" iyy="2.74413054377e-05" iyz="0.0" izz="0.000923727713157"/>
    </inertial>
  </link>
  <gazebo reference="tubepar_9Z">
    <selfCollide>True</selfCollide>
    <material>Gazebo/Grey</material>
    <mu1>0.05</mu1>
    <mu2>0.05</mu2>
    <kp>100000</kp>
    <kd>1</kd>
    <minDepth>0.001</minDepth>
    <maxVel>100</maxVel>
  </gazebo>
  <link name="tubepar_11Z">
    <visual>
      <origin rpy="0 0 0" xyz="-2.94658008559e-18 -0.3 9.0066843052e-18"/>
      <geometry>
        <mesh filename="package://openmeta_generated_urdf_package/meshes/tubepar_11z_prt.stl" scale="0.001 0.001 0.001"/>
      </geometry>
    </visual>
    <collision>
      <origin rpy="0 0 0" xyz="-2.94658008559e-18 -0.3 9.0066843052e-18"/>
      <geometry>
        <mesh filename="package://openmeta_generated_urdf_package/meshes/tubepar_11z_prt.stl" scale="0.001 0.001 0.001"/>
      </geometry>
    </collision>
    <inertial>
      <origin rpy="0 0 0" xyz="-2.94658008559e-18 -0.15 9.0066843052e-18"/>
      <mass value="0.12133427279164029"/>
      <inertia ixx="0.000923727684155" ixy="0.0" ixz="0.0" iyy="2.74413054377e-05" iyz="0.0" izz="0.000923727713157"/>
    </inertial>
  </link>
  <gazebo reference="tubepar_11Z">
    <selfCollide>True</selfCollide>
    <material>Gazebo/Grey</material>
    <mu1>0.05</mu1>
    <mu2>0.05</mu2>
    <kp>100000</kp>
    <kd>1</kd>
    <minDepth>0.001</minDepth>
    <maxVel>100</maxVel>
  </gazebo>
  <link name="hebi_x5_4_6Z">
    <visual>
      <origin rpy="0 0 0" xyz="-5.81782375942e-17 -2.3939184e-18 0.015"/>
      <geometry>
        <mesh filename="package://openmeta_generated_urdf_package/meshes/hebi_x5_4_6z_prt.stl" scale="0.001 0.001 0.001"/>
      </geometry>
    </visual>
    <collision>
      <origin rpy="0 0 0" xyz="-5.81782375942e-17 -2.3939184e-18 0.015"/>
      <geometry>
        <mesh filename="package://openmeta_generated_urdf_package/meshes/hebi_x5_4_6z_prt.stl" scale="0.001 0.001 0.001"/>
      </geometry>
    </collision>
    <inertial>
      <origin rpy="0 0 0" xyz="-0.0142019322139 -0.00151173442654 0.0150064707722"/>
      <mass value="0.33507040082811385"/>
      <inertia ixx="0.000139243898497" ixy="-1.88809652748e-05" ixz="1.26840661154e-08" iyy="0.000241540500785" iyz="1.28229789324e-07" izz="0.000330481488128"/>
    </inertial>
  </link>
  <gazebo reference="hebi_x5_4_6Z">
    <selfCollide>True</selfCollide>
    <material>Gazebo/Red</material>
    <mu1>0.1</mu1>
    <mu2>0.1</mu2>
    <kp>100000</kp>
    <kd>1</kd>
    <minDepth>0.001</minDepth>
    <maxVel>100</maxVel>
    <sensor name="HEBI/Elbow/imu_sensor" type="imu">
      <always_on>true</always_on>
      <update_rate>100</update_rate>
      <visualize>true</visualize>
      <plugin filename="libgazebo_ros_imu_sensor.so" name="imu_plugin">
        <topicName>/hebiros_gazebo_plugin/imu/HEBI/Elbow</topicName>
        <bodyName>HEBI/Elbow/imu_link</bodyName>
        <updateRateHZ>10.0</updateRateHZ>
        <gaussianNoise>0.0</gaussianNoise>
        <xyzOffset>0.025 0 0.003</xyzOffset>
        <rpyOffset>0 0 0</rpyOffset>
        <frameName>HEBI/Elbow/imu_link</frameName>
      </plugin>
      <pose>0 0 0 0 0 0</pose>
    </sensor>
  </gazebo>
  <link name="hebi_x5_4_3Z">
    <visual>
      <origin rpy="0 0 0" xyz="-5.55318730444e-17 -2.49799181e-18 0.015"/>
      <geometry>
        <mesh filename="package://openmeta_generated_urdf_package/meshes/hebi_x5_4_3z_prt.stl" scale="0.001 0.001 0.001"/>
      </geometry>
    </visual>
    <collision>
      <origin rpy="0 0 0" xyz="-5.55318730444e-17 -2.49799181e-18 0.015"/>
      <geometry>
        <mesh filename="package://openmeta_generated_urdf_package/meshes/hebi_x5_4_3z_prt.stl" scale="0.001 0.001 0.001"/>
      </geometry>
    </collision>
    <inertial>
      <origin rpy="0 0 0" xyz="-0.0142019322139 -0.00151173442654 0.0150064707722"/>
      <mass value="0.33507040082811385"/>
      <inertia ixx="0.000139243898497" ixy="-1.88809652748e-05" ixz="1.26840661154e-08" iyy="0.000241540500785" iyz="1.28229789324e-07" izz="0.000330481488128"/>
    </inertial>
  </link>
  <gazebo reference="hebi_x5_4_3Z">
    <selfCollide>True</selfCollide>
    <material>Gazebo/Red</material>
    <mu1>0.1</mu1>
    <mu2>0.1</mu2>
    <kp>100000</kp>
    <kd>1</kd>
    <minDepth>0.001</minDepth>
    <maxVel>100</maxVel>
    <sensor name="HEBI/Base/imu_sensor" type="imu">
      <always_on>true</always_on>
      <update_rate>100</update_rate>
      <visualize>true</visualize>
      <plugin filename="libgazebo_ros_imu_sensor.so" name="imu_plugin">
        <topicName>/hebiros_gazebo_plugin/imu/HEBI/Base</topicName>
        <bodyName>HEBI/Base/imu_link</bodyName>
        <updateRateHZ>10.0</updateRateHZ>
        <gaussianNoise>0.0</gaussianNoise>
        <xyzOffset>0.025 0 0.003</xyzOffset>
        <rpyOffset>0 0 0</rpyOffset>
        <frameName>HEBI/Base/imu_link</frameName>
      </plugin>
      <pose>0 0 0 0 0 0</pose>
    </sensor>
  </gazebo>
  <link name="hebi_x5_9_7Z">
    <visual>
      <origin rpy="0 0 0" xyz="-5.35847694878e-17 2.59237076204e-17 0.015"/>
      <geometry>
        <mesh filename="package://openmeta_generated_urdf_package/meshes/hebi_x5_9_7z_prt.stl" scale="0.001 0.001 0.001"/>
      </geometry>
    </visual>
    <collision>
      <origin rpy="0 0 0" xyz="-5.35847694878e-17 2.59237076204e-17 0.015"/>
      <geometry>
        <mesh filename="package://openmeta_generated_urdf_package/meshes/hebi_x5_9_7z_prt.stl" scale="0.001 0.001 0.001"/>
      </geometry>
    </collision>
    <inertial>
      <origin rpy="0 0 0" xyz="-0.0142019322139 -0.00151173442654 0.0150064707722"/>
      <mass value="0.3601223934133934"/>
      <inertia ixx="0.000149654657264" ixy="-2.029262623e-05" ixz="1.36324075072e-08" iyy="0.000259599603648" iyz="1.37817063293e-07" izz="0.000355190384437"/>
    </inertial>
  </link>
  <gazebo reference="hebi_x5_9_7Z">
    <selfCollide>True</selfCollide>
    <material>Gazebo/Red</material>
    <mu1>0.1</mu1>
    <mu2>0.1</mu2>
    <kp>100000</kp>
    <kd>1</kd>
    <minDepth>0.001</minDepth>
    <maxVel>100</maxVel>
    <sensor name="HEBI/Shoulder/imu_sensor" type="imu">
      <always_on>true</always_on>
      <update_rate>100</update_rate>
      <visualize>true</visualize>
      <plugin filename="libgazebo_ros_imu_sensor.so" name="imu_plugin">
        <topicName>/hebiros_gazebo_plugin/imu/HEBI/Shoulder</topicName>
        <bodyName>HEBI/Shoulder/imu_link</bodyName>
        <updateRateHZ>10.0</updateRateHZ>
        <gaussianNoise>0.0</gaussianNoise>
        <xyzOffset>0.025 0 0.003</xyzOffset>
        <rpyOffset>0 0 0</rpyOffset>
        <frameName>HEBI/Shoulder/imu_link</frameName>
      </plugin>
      <pose>0 0 0 0 0 0</pose>
    </sensor>
  </gazebo>
</robot>
